Workbook
Name \c: #REF!
Name \d: #REF!
Name \i: #REF!
Name A: #REF!
Name A: fism!#REF!
Name A_impresión_IM: #REF!
Name julian: #REF!
Name LUGO: #REF!
Name MAS: #REF!
Name MES: #REF!
Name MMES: #REF!

Sheet fism
A2: CEDULA DE FINIQUITO DE OBRA
A3: EJERCICIO: 2022
C4: CLAVE MPAL: | E4: 067
C5: FECHA:
C6: HOJA: | F6: DE
C7: MES: | D7: octubre
A8: DATOS GENERALES
A10: MUNICIPIO : | B10: OCOZOCOAUTLA DE ESPINOSA | C10: MUNICIPIO : | D10: OCOZOCOAUTLA DE ESPINOSA
A12: NOMBRE DEL PROYECTO | B12: EQUIPAMIENTO DE ESPACIOS MULTIDEPORTIVOS (AUDITORIO MUNICIPAL)
A14: CLAVES PRESUPUESTALES: | C14: NO. OBRA | D14: OP01
A15: PROGRAMA : | B15: programa de pavimentación | C15: SUBPROGRAMA: | D15: bacheo
A17: SITUACION FINANCIERA
A18: PRESUPUESTO PROGRAMADO | C18: PRESUPUESTO DEVENGADO | E18: SALDO
A19: FUENTE DE FINANCIAMIENTO: $0.00 | C19: FUENTE DE FINANCIAMIENTO | D19: 36524.25 | E19: FUENTE DE FINANCIAMIENTO | F19: -36524.25
A20: TOTAL: $0.00 | C20: TOTAL | D20: =D19 -> 0 | E20: TOTAL | F20: -36524.25
A21: Modalidad de Ejecución: C O N T R A T O / A D M I N I S T R A C I Ó N D I R E C T A
A22: GEORREFERENCIACION | C22: PERIODO DE EJECUCIÓN
A23: LATITUD | B23: LONGITUD | C23: PROGRAMADO | D23: REAL | F23: FINANCIERO
A24: 2541254254145 | B24: -36598544121 | C24: INICIO | D24: TERMINO | F24: 95.00%
A25: NO. CONTRATO | C25: 01/01/1900 | D25: 16/02/2023
A26: PM/DOPM/FISM/A.D.001-2022
A27: CONTRATISTA | C27: OBSERVACIONES
A28: AYUNTAMIENTO (ADMINIISTRACION DIRECTA) | C28: se realizaron los trabajos sin ninguna complicación
A30: DESCRIPCION DE LA OBRA
A31: EQUIPAMIENTO DE ESPACIOS MULTIDEPORTIVOS (AUDITORIO MUNICIPAL)
D35: COORDENADAS
D36: LAT 2541254254145° | E36: LONG -36598544121°

Sheet GENERADOR
B1: H. AYUNTAMIENTO MUNICIPAL CONSTITUCIONAL DE TZIMOL, CHIAPAS.
B2: 2018 - 2021
B3: DIRECCIÓN DE OBRAS PÚBLICAS MUNICIPALES
B7: LOCALIDAD: LA MESILLA
B8: MUNICIPIO: TZIMOL, CHIAPAS.
B9: OBRA: CONSTRUCCION DEL SISTEMA DE ALCANTARILLADO SANITARIO
A12: OBRA: | B12: CONSTRUCCION DEL SISTEMA DE ALCANTARILLADO SANITARIO
A14: LOCALIDAD: | B14: LA MESILLA
A15: NUMEROS GENERADORES
A16: CODIGO | B16: CONCEPTO | C16: UNIDAD | D16: LOCALIZACION | G16: PZAS. | H16: LARGO | I16: ANCHO | J16: ALTO | K16: RESULTADO | L16: OBSERVACIONES
D17: EJE | E17: TRAMO | F17: TIPO
B18: RED DE ATARJEAS
A19: A0501 | B19: LIMPIA Y TRAZO
A20: =fism!#REF! -> #REF! | B20: =fism!#REF! -> #REF! | C20: M2 | H20: 1100 | I20: 1 | K20: =H20*I20 -> 1100
A22: =fism!#REF! -> #REF! | B22: =fism!#REF! -> #REF! | C22: ML | H22: 1100 | K22: =H22 -> 1100
A24: A10 | B24: PRELIMINARES
A25: A1001 | B25: RUPTURA DE PAVIMENTOS
A26: =fism!#REF! -> #REF! | B26: =fism!#REF! -> #REF! | C26: M3 | H26: =H22 -> 1100 | I26: 0.7 | J26: 0.15 | K26: =H26*I26*J26 -> 115.5
A29: A1002 | B29: REPOSICION DE PAVIMENTOS
A30: =fism!#REF! -> #REF! | B30: =fism!#REF! -> #REF! | C30: M3 | H30: =H26 -> 1100 | I30: =I26 -> 0.7 | J30: =J26 -> 0.15 | K30: =H30*I30*J30 -> 115.5
A35: A1011 | B35: EXCAVACION EN ZANJA
A36: =fism!#REF! -> #REF! | B36: =fism!#REF! -> #REF! | C36: =+[4]Presupuesto!D26 -> M3 | I36: 1100 | J36: 0.4 | K36: =I36*J36 -> 440 | L36: 40% EXC. A MANO PARA PROTEGER TUBERIA DE AGUA Y TOMAS EXISTENTE
H37: Material "B" | J37: 0.4 | K37: =K36*0.5 -> 220
A42: =fism!#REF! -> #REF! | B42: =fism!#REF! -> #REF! | C42: M3 | I42: 140 | J42: 1 | K42: =I42*J42 -> 140
H43: Material "B" | J43: 0.4 | K43: =K42*J43 -> 56
A48: =fism!#REF! -> #REF! | B48: =fism!#REF! -> #REF! | C48: M3 | I48: 16 | J48: 1 | K48: =I48*J48 -> 16
H49: Material "B" | J49: 0.4 | K49: =K48*J49 -> 6.4
A54: =fism!#REF! -> #REF! | B54: =fism!#REF! -> #REF! | C54: M3 | I54: 1100 | J54: 0.6 | K54: =I54*J54 -> 660 | L54: 50% EXC. A MAQUINA
H55: Material "B" | J55: 0.4 | K55: =K54*J55 -> 264
A61: =fism!#REF! -> #REF! | B61: =fism!#REF! -> #REF! | C61: M3 | I61: 1100 | J61: 0.6 | K61: =I61*J61 -> 660 | L61: 50% EXC. A MAQUINA
H62: Material "C" | J62: 0.6 | K62: =K61*J62 -> 396
A67: =fism!#REF! -> #REF! | B67: =fism!#REF! -> #REF! | C67: M3 | I67: 110 | J67: 0.6 | K67: =I67*J67 -> 66 | L67: 50% EXC. A MAQUINA
H68: Material "C" | J68: 0.6 | K68: =K67*J68 -> 39.6
A73: S/C | B73: EXCAVACION CON APOYO DE EQUIPO MANUAL Y MECANICO PARA ZANJAS EN MATERIAL "C" EN SECO, CON EXTRACCION DE REZAGA A MANO, INCLUYE: AFLOJE, AMACICE, LIMPIEZA DE PLANTILLA Y TALUDES, ACARREO A 10 M DEL EJE DE LA MISMA Y CONSERVACION DE LA EXCAVACION HASTA LA INSTALACION SATISFACTORIA DE LA TUBERIA: DE 4.00 A 6.00 MTS. DE PROFUNDIDAD INCLUYE TODO LO NECESARIO PARA SU CORRECTA EJECUCION. | C73: M3 | I73: 110 | J73: 0.6 | K73: =I73*J73 -> 66 | L73: 50% EXC. A MAQUINA
H74: Material "C" | J74: 0.6 | K74: =K73*J74 -> 39.6
A79: =fism!#REF! -> #REF! | B79: =fism!#REF! -> #REF! | C79: M3 | D79: VOL DE EXCAVACION TOTAL | K79: =+I54 -> 1100
D80: VOL.TOTAL DE PAVIMENTO | K80: =+K26*-1 -> -115.5
D81: MENOS VOL. DE TUBERIA | G81: =+K112 -> 1800 | H81: AREA | I81: 0.07 | K81: =G81*I81*(-1) -> -126
J82: TOTAL | K82: =SUM(K79:K81) -> 858.5
A84: =fism!#REF! -> #REF! | B84: =fism!#REF! -> #REF! | C84: M3-km | G84: VOL. | H84: =+K82 -> 858.5 | I84: 2 | K84: =H84*I84 -> 1717
...
